<?xml version="1.0" encoding="UTF-8"?>
<robot name="ridgeback_ur5">
  <joint name="dummy_base_prismatic_y_joint" type="prismatic">
    <origin xyz="0. 0. 0." rpy="0. 0. 0."/>
    <parent link="dummy_base_x"/>
    <child link="dummy_base_y"/>
    <axis xyz="1. 0. 0."/>
    <limit lower="-600.2800293" upper="600.2800293" effort="4800." velocity="15."/>
  </joint>
  <joint name="dummy_base_revolute_z_joint" type="revolute">
    <origin xyz="0. 0. 0." rpy="-1.5707964 -1.5707964 0. "/>
    <parent link="dummy_base_y"/>
    <child link="base_link"/>
    <axis xyz="1. 0. 0."/>
    <limit lower="-600.2800208" upper="600.2800208" effort="4800." velocity="15.0000002"/>
  </joint>
  <joint name="base_lidar" type="fixed">
    <origin xyz="0. 0. 0." rpy="-1.5707964 -1.5707964 0. "/>
    <parent link="base_link"/>
    <child link="tim781"/>
    <axis xyz="1. 0. 0."/>
    <limit lower="-600.2800208" upper="600.2800208" effort="4800." velocity="15.0000002"/>
  </joint>
  <joint name="ur_arm_elbow_joint" type="revolute">
    <origin xyz="0. 0. 0.425" rpy="0. 0. 0."/>
    <parent link="ur_arm_upper_arm_link"/>
    <child link="ur_arm_forearm_link"/>
    <axis xyz="1. 0. 0."/>
    <limit lower="-3.1415927" upper="3.1415927" effort="9000." velocity="3.1415927"/>
  </joint>
  <joint name="ur_arm_shoulder_lift_joint" type="revolute">
    <origin xyz="0. 0. 0." rpy="0. 0. -1.5707964"/>
    <parent link="ur_arm_shoulder_link"/>
    <child link="ur_arm_upper_arm_link"/>
    <axis xyz="1. 0. 0."/>
    <limit lower="-6.2831853" upper="6.2831853" effort="9000." velocity="3.1415927"/>
  </joint>
  <joint name="ur_arm_shoulder_pan_joint" type="revolute">
    <origin xyz="0.369159 0. 0. " rpy="-3.1415925 0. 0. "/>
    <parent link="base_link"/>
    <child link="ur_arm_shoulder_link"/>
    <axis xyz="1. 0. 0."/>
    <limit lower="-6.2831853" upper="6.2831853" effort="9000." velocity="3.1415927"/>
  </joint>
  <joint name="ur_arm_wrist_1_joint" type="revolute">
    <origin xyz="0.10915 0. 0.39225" rpy="0. 0. 0."/>
    <parent link="ur_arm_forearm_link"/>
    <child link="ur_arm_wrist_1_link"/>
    <axis xyz="1. 0. 0."/>
    <limit lower="-6.2831853" upper="6.2831853" effort="1680." velocity="3.1415927"/>
  </joint>
  <joint name="ur_arm_wrist_2_joint" type="revolute">
    <origin xyz="-0. -0.09465 0. " rpy="0. 0. -1.5707964"/>
    <parent link="ur_arm_wrist_1_link"/>
    <child link="ur_arm_wrist_2_link"/>
    <axis xyz="1. 0. 0."/>
    <limit lower="-6.2831853" upper="6.2831853" effort="1680." velocity="3.1415927"/>
  </joint>
  <joint name="ur_arm_wrist_3_joint" type="revolute">
    <origin xyz="-0. 0.0823 0. " rpy="-0.0000001 -0.0000001 0."/>
    <parent link="ur_arm_wrist_2_link"/>
    <child link="ur_arm_wrist_3_link"/>
    <axis xyz="1. 0. 0."/>
    <limit lower="-6.2831853" upper="6.2831853" effort="1680." velocity="3.1415927"/>
  </joint>
  <joint name="ur_arm_wrist_3_sensor_joint" type="fixed">
    <origin xyz="-0. 0. 0. " rpy="-0.0000001 -0.0000001 1.5707964"/>
    <parent link="ur_arm_wrist_3_link"/>
    <child link="hawk_v1_1_nominal"/>
  </joint>
  <link name="base_link">
    <visual>
      <origin xyz="0. 0. 0." rpy="0. 0. 0. "/>
      <geometry>
        <mesh filename="package://rur5/meshes/base_link_visuals_mesh_0.obj" scale="1. 1. 1."/>
      </geometry>
    </visual>
    <visual>
      <origin xyz="0. 0. 0. " rpy="1.57 -1.57 1.57"/>
      <geometry>
        <mesh filename="package://rur5/meshes/base_link_visuals_mesh_1.obj" scale="1. 1. 1."/>
      </geometry>
    </visual>
    <visual>
      <origin xyz=" 0. -0.319 0.05" rpy="1.57 -0. 0."/>
      <geometry>
        <mesh filename="package://rur5/meshes/base_link_visuals_mesh_2.obj" scale="1. 1. 1."/>
      </geometry>
    </visual>
    <visual>
      <origin xyz="0.2755 0.319 0.05 " rpy="1.57 0. 0. "/>
      <geometry>
        <mesh filename="package://rur5/meshes/base_link_visuals_mesh_3.obj" scale="1. 1. 1."/>
      </geometry>
    </visual>
    <visual>
      <origin xyz="0.2755 -0.319 0.05 " rpy="1.57 0. 0. "/>
      <geometry>
        <mesh filename="package://rur5/meshes/base_link_visuals_mesh_4.obj" scale="1. 1. 1."/>
      </geometry>
    </visual>
    <visual>
      <origin xyz="0. -0.319 0.05" rpy="1.57 -0. 0."/>
      <geometry>
        <mesh filename="package://rur5/meshes/base_link_visuals_mesh_5.obj" scale="1. 1. 1."/>
      </geometry>
    </visual>
    <visual>
      <origin xyz=" -0.2755 0.319 0.05" rpy="1.57 0. 0. "/>
      <geometry>
        <mesh filename="package://rur5/meshes/base_link_visuals_mesh_6.obj" scale="1. 1. 1."/>
      </geometry>
    </visual>
    <visual>
      <origin xyz="-0.2755 -0.319 0.05 " rpy="1.57 0. 0. "/>
      <geometry>
        <mesh filename="package://rur5/meshes/mesh_7.obj" scale="1. 1. 1."/>
      </geometry>
    </visual>
    <visual>
      <origin xyz="0. 0. 0." rpy="0. 0. 0. "/>
      <geometry>
        <mesh filename="package://rur5/meshes/mesh_8.obj" scale="1. 1. 1."/>
      </geometry>
    </visual>
    <visual>
      <origin xyz="0. 0. 0." rpy="0. 0. 0. "/>
      <geometry>
        <mesh filename="package://rur5/meshes/mesh_9.obj" scale="1. 1. 1."/>
      </geometry>
    </visual>
    <visual>
      <origin xyz="0. 0. 0." rpy="0. 0. 0. "/>
      <geometry>
        <mesh filename="package://rur5/meshes/mesh_10.obj" scale="1. 1. 1."/>
      </geometry>
    </visual>
    <visual>
      <origin xyz="0. 0. 0." rpy="0. 0. 0. "/>
      <geometry>
        <mesh filename="package://rur5/meshes/mesh_11.obj" scale="1. 1. 1."/>
      </geometry>
    </visual>
    <visual>
      <origin xyz="0. 0. 0." rpy="0. 0. 0. "/>
      <geometry>
        <mesh filename="package://rur5/meshes/mesh_12.obj" scale="1. 1. 1."/>
      </geometry>
    </visual>
    <visual>
      <origin xyz="0. 0. 0." rpy="0. 0. 0. "/>
      <geometry>
        <mesh filename="package://rur5/meshes/mesh_13.obj" scale="1. 1. 1."/>
      </geometry>
    </visual>
    <visual>
      <origin xyz="0. 0. 0." rpy="0. 0. 0. "/>
      <geometry>
        <mesh filename="package://rur5/meshes/mesh_14.obj" scale="1. 1. 1."/>
      </geometry>
    </visual>
    <visual>
      <origin xyz="0.28 0. 0. " rpy="0. 0. 0. "/>
      <geometry>
        <mesh filename="package://rur5/meshes/mesh_15.obj" scale="1. 1. 1."/>
      </geometry>
    </visual>
    <visual>
      <origin xyz="0. 0. 0." rpy="0. 0. 0. "/>
      <geometry>
        <mesh filename="package://rur5/meshes/base_link_collisions_mesh_0.obj" scale="1. 1. 1."/>
      </geometry>
    </visual>
    <visual>
      <origin xyz="0. 0. 0." rpy="0. 0. 0. "/>
      <geometry>
        <mesh filename="package://rur5/meshes/base_link_collisions_mesh_5.obj" scale="1. 1. 1."/>
      </geometry>
    </visual>
    <visual>
      <origin xyz=" -0.2755 0.319 0.05" rpy="1.57 0. 0. "/>
      <geometry>
        <mesh filename="package://rur5/meshes/base_link_collisions_mesh_6.obj" scale="1. 1. 1."/>
      </geometry>
    </visual>
    <collision>
      <origin xyz="0. 0. 0." rpy="0. 0. 0. "/>
      <geometry>
        <mesh filename="package://rur5/meshes/base_link_collisions_mesh_0.obj" scale="1. 1. 1."/>
      </geometry>
    </collision>
    <collision>
      <origin xyz="0.05 0.2755 -0.319 " rpy="0. 0. 0. "/>
      <geometry>
        <cylinder radius="0.0759" length="0.079"/>
      </geometry>
    </collision>
    <collision>
      <origin xyz="0.05 -0.2755 -0.319 " rpy="0. 0. 0. "/>
      <geometry>
        <cylinder radius="0.0759" length="0.079"/>
      </geometry>
    </collision>
    <collision>
      <origin xyz="0.05 0.2755 0.319 " rpy="0. 0. 0. "/>
      <geometry>
        <cylinder radius="0.0759" length="0.079"/>
      </geometry>
    </collision>
    <collision>
      <origin xyz="0.05 -0.2755 0.319 " rpy="0. 0. 0. "/>
      <geometry>
        <cylinder radius="0.0759" length="0.079"/>
      </geometry>
    </collision>
    <collision>
      <origin xyz="0. 0. 0." rpy="0. 0. 0. "/>
      <geometry>
        <mesh filename="package://rur5/meshes/base_link_collisions_mesh_5.obj" scale="1. 1. 1."/>
      </geometry>
    </collision>
    <collision>
      <origin xyz="0.28 0. 0. " rpy="0. 0. 0. "/>
      <geometry>
        <mesh filename="package://rur5/meshes/base_link_collisions_mesh_6.obj" scale="1. 1. 1."/>
      </geometry>
    </collision>
  </link>
  <link name="dummy_base_x">
    <inertial>
      <origin xyz="0. 0. 0." rpy="0. 0. 0."/>
      <mass value="0.0001"/>
      <inertia ixx="0." ixy="0." ixz="0." iyy="0." iyz="0." izz="0."/>
    </inertial>
  </link>
  <link name="dummy_base_y">
    <inertial>
      <origin xyz="0. 0. 0." rpy="0. 0. 0."/>
      <mass value="0.0001"/>
      <inertia ixx="0." ixy="0." ixz="0." iyy="0." iyz="0." izz="0."/>
    </inertial>
  </link>
  <link name="ur_arm_forearm_link">
    <inertial>
      <origin xyz=" 0. 0. 0.0165" rpy="1.57 -0. -1.57"/>
      <mass value="2.2750001"/>
      <inertia ixx="0." ixy="0." ixz="0." iyy="0." iyz="0." izz="0."/>
    </inertial>
    <visual>
      <origin xyz=" 0. 0. 0.0165" rpy="1.57 -0. -1.57"/>
      <geometry>
        <mesh filename="package://rur5/meshes/ur_arm_forearm_link_visuals.obj" scale="1. 1. 1."/>
      </geometry>
    </visual>
    <visual>
      <origin xyz=" 0. 0. 0.0165" rpy="1.57 -0. -1.57"/>
      <geometry>
        <mesh filename="package://rur5/meshes/ur_arm_forearm_link_collisions.obj" scale="1. 1. 1."/>
      </geometry>
    </visual>
    <collision>
      <origin xyz=" 0. 0. 0.0165" rpy="1.57 -0. -1.57"/>
      <geometry>
        <mesh filename="package://rur5/meshes/ur_arm_forearm_link_collisions.obj" scale="1. 1. 1."/>
      </geometry>
    </collision>
  </link>
  <link name="ur_arm_shoulder_link">
    <inertial>
      <origin xyz="0. 0. 0." rpy="0. 0. 3.14 "/>
      <mass value="3.7"/>
      <inertia ixx="0." ixy="0." ixz="0." iyy="0." iyz="0." izz="0."/>
    </inertial>
    <visual>
      <origin xyz="0. 0. 0." rpy="0. 0. 3.14 "/>
      <geometry>
        <mesh filename="package://rur5/meshes/ur_arm_shoulder_link_visuals.obj" scale="1. 1. 1."/>
      </geometry>
    </visual>
    <visual>
      <origin xyz="0. 0. 0." rpy="0. 0. 3.14 "/>
      <geometry>
        <mesh filename="package://rur5/meshes/ur_arm_shoulder_link_collisions.obj" scale="1. 1. 1."/>
      </geometry>
    </visual>
    <collision>
      <origin xyz="0. 0. 0." rpy="0. 0. 3.14 "/>
      <geometry>
        <mesh filename="package://rur5/meshes/ur_arm_shoulder_link_collisions.obj" scale="1. 1. 1."/>
      </geometry>
    </collision>
  </link>
  <link name="ur_arm_upper_arm_link">
    <inertial>
      <origin xyz=" 0. 0. 0.13585" rpy="-1.57 3.14 1.57"/>
      <mass value="8.3929996"/>
      <inertia ixx="0." ixy="0." ixz="0." iyy="0." iyz="0." izz="0."/>
    </inertial>
    <visual>
      <origin xyz=" 0. 0. 0.13585" rpy="-1.57 3.14 1.57"/>
      <geometry>
        <mesh filename="package://rur5/meshes/ur_arm_upper_arm_link_visuals.obj" scale="1. 1. 1."/>
      </geometry>
    </visual>
    <visual>
      <origin xyz=" 0. 0. 0.13585" rpy="-1.57 3.14 1.57"/>
      <geometry>
        <mesh filename="package://rur5/meshes/ur_arm_upper_arm_link_collisions.obj" scale="1. 1. 1."/>
      </geometry>
    </visual>
    <collision>
      <origin xyz=" 0. 0. 0.13585" rpy="-1.57 3.14 1.57"/>
      <geometry>
        <mesh filename="package://rur5/meshes/ur_arm_upper_arm_link_collisions.obj" scale="1. 1. 1."/>
      </geometry>
    </collision>
  </link>
  <link name="ur_arm_wrist_1_link">
    <inertial>
      <origin xyz="0. 0. -0.093 " rpy="-1.57 3.14 3.14 "/>
      <mass value="1.219"/>
      <inertia ixx="0." ixy="0." ixz="0." iyy="0." iyz="0." izz="0."/>
    </inertial>
    <visual>
      <origin xyz=" 0. 0. -0.093" rpy="-1.57 3.14 3.14 "/>
      <geometry>
        <mesh filename="package://rur5/meshes/ur_arm_wrist_1_link_visuals.obj" scale="1. 1. 1."/>
      </geometry>
    </visual>
    <visual>
      <origin xyz="0. 0. -0.093 " rpy="-1.57 3.14 3.14 "/>
      <geometry>
        <mesh filename="package://rur5/meshes/ur_arm_wrist_1_link_collisions.obj" scale="1. 1. 1."/>
      </geometry>
    </visual>
    <collision>
      <origin xyz="0. 0. -0.093 " rpy="-1.57 3.14 3.14 "/>
      <geometry>
        <mesh filename="package://rur5/meshes/ur_arm_wrist_1_link_collisions.obj" scale="1. 1. 1."/>
      </geometry>
    </collision>
  </link>
  <link name="ur_arm_wrist_2_link">
    <inertial>
      <origin xyz="0. 0.005 -0.095" rpy="0. 0. 0. "/>
      <mass value="1.219"/>
      <inertia ixx="0." ixy="0." ixz="0." iyy="0." iyz="0." izz="0."/>
    </inertial>
    <visual>
      <origin xyz="0. 0.005 -0.095" rpy="0. 0. 0. "/>
      <geometry>
        <mesh filename="package://rur5/meshes/ur_arm_wrist_2_link_visuals.obj" scale="1. 1. 1."/>
      </geometry>
    </visual>
    <visual>
      <origin xyz="0. 0.005 -0.095" rpy="0. 0. 0. "/>
      <geometry>
        <mesh filename="package://rur5/meshes/ur_arm_wrist_2_link_collisions.obj" scale="1. 1. 1."/>
      </geometry>
    </visual>
    <collision>
      <origin xyz="0. 0.005 -0.095" rpy="0. 0. 0. "/>
      <geometry>
        <mesh filename="package://rur5/meshes/ur_arm_wrist_2_link_collisions.obj" scale="1. 1. 1."/>
      </geometry>
    </collision>
  </link>
  <link name="ur_arm_wrist_3_link">
    <inertial>
      <origin xyz=" -0. 0. -0.083" rpy="1.57 0. 0. "/>
      <mass value="0.1879"/>
      <inertia ixx="0." ixy="0." ixz="0." iyy="0." iyz="0." izz="0."/>
    </inertial>
    <visual>
      <origin xyz=" -0. 0. -0.083" rpy="1.57 0. 0.  "/>
      <geometry>
        <mesh filename="package://rur5/meshes/ur_arm_wrist_3_link_visuals.obj" scale="1. 1. 1."/>
      </geometry>
    </visual>
    <visual>
      <origin xyz=" -0. 0. -0.083" rpy="1.57 0. 0.  "/>
      <geometry>
        <mesh filename="package://rur5/meshes/ur_arm_wrist_3_link_collisions.obj" scale="1. 1. 1."/>
      </geometry>
    </visual>
    <collision>
      <origin xyz=" -0. 0. -0.083" rpy="1.57 0. 0. "/>
      <geometry>
        <mesh filename="package://rur5/meshes/ur_arm_wrist_3_link_collisions.obj" scale="1. 1. 1."/>
      </geometry>
    </collision>
  </link>
  <material name="white">
    <color rgba="1 1 1 1"/>
  </material>
  <link name="hawk_v1_1_nominal">
    <visual>
      <origin xyz=" 0.005 0. 0." rpy="0. 0. 1.57  "/>
      <material name="white"/>
      <geometry>
        <box size="0.2 0.01 0.04"/>
      </geometry>
      
    </visual>

  </link>
  <link name="tim781">
    <visual>
      <origin xyz=" 0. 0. 0." rpy="0. 0. 1.57  "/>
      <material name="white"/>
      <geometry>
        <cylinder length="0.05" radius="0.05"/>
      </geometry>
      
    </visual>

  </link>
</robot>
